Workbook

Sheet Condomínios Catanduva
B2: Condomínios verticais de Catanduva/SP — 106 identificados
B3: Nome, endereço e bairro vêm de fontes públicas. A coluna Unidades é amarela porque precisa ser confirmada em campo.
B6: # | C6: Condomínio | D6: Endereço | E6: Bairro | F6: Tipo | G6: Já é cliente? | H6: Unidades | I6: Faixa | J6: Mensalidade | K6: Receita 12 meses | L6: Síndico | M6: Telefone | N6: Status | O6: Observações
B7: 1 | C7: Condomínio Edifício Alagoas | D7: Rua Alagoas, 340 | E7: Centro | F7: Residencial | I7: =IF(H7="","",IF(H7<=Preço!$C$7,Preço!$B$7,IF(H7<=Preço!$C$8,Preço!$B$8,IF(H7<=Preço!$C$9,Preço!$B$9,Preço!$B$10)))) | J7: =IF(H7="","",Preço!$D$7+MAX(0,MIN(H7,Preço!$C$8)-Preço!$C$7)*Preço!$D$8+MAX(0,MIN(H7,Preço!$C$9)-Preço!$C$8)*Preço!$D$9+MAX(0,H7-Preço!$C$9)*Preço!$D$10) | K7: =IF(H7="","",J7*12)
B8: 2 | C8: Condomínio Edifício Amazonas | D8: Rua Minas Gerais, 106 | E8: Centro | F8: Residencial | I8: =IF(H8="","",IF(H8<=Preço!$C$7,Preço!$B$7,IF(H8<=Preço!$C$8,Preço!$B$8,IF(H8<=Preço!$C$9,Preço!$B$9,Preço!$B$10)))) | J8: =IF(H8="","",Preço!$D$7+MAX(0,MIN(H8,Preço!$C$8)-Preço!$C$7)*Preço!$D$8+MAX(0,MIN(H8,Preço!$C$9)-Preço!$C$8)*Preço!$D$9+MAX(0,H8-Preço!$C$9)*Preço!$D$10) | K8: =IF(H8="","",J8*12)
B9: 3 | C9: Condomínio Edifício Arnaldo Bittencourt | D9: Rua Sergipe, 197 | E9: Centro | F9: Residencial | I9: =IF(H9="","",IF(H9<=Preço!$C$7,Preço!$B$7,IF(H9<=Preço!$C$8,Preço!$B$8,IF(H9<=Preço!$C$9,Preço!$B$9,Preço!$B$10)))) | J9: =IF(H9="","",Preço!$D$7+MAX(0,MIN(H9,Preço!$C$8)-Preço!$C$7)*Preço!$D$8+MAX(0,MIN(H9,Preço!$C$9)-Preço!$C$8)*Preço!$D$9+MAX(0,H9-Preço!$C$9)*Preço!$D$10) | K9: =IF(H9="","",J9*12)
B10: 4 | C10: Condomínio Edifício Arquiteto Roberto Yazigi | D10: Rua 13 de Maio, 337 | E10: Centro | F10: Residencial | I10: =IF(H10="","",IF(H10<=Preço!$C$7,Preço!$B$7,IF(H10<=Preço!$C$8,Preço!$B$8,IF(H10<=Preço!$C$9,Preço!$B$9,Preço!$B$10)))) | J10: =IF(H10="","",Preço!$D$7+MAX(0,MIN(H10,Preço!$C$8)-Preço!$C$7)*Preço!$D$8+MAX(0,MIN(H10,Preço!$C$9)-Preço!$C$8)*Preço!$D$9+MAX(0,H10-Preço!$C$9)*Preço!$D$10) | K10: =IF(H10="","",J10*12)
B11: 5 | C11: Condomínio Edifício Bahia | D11: Rua Bahia, 321 | E11: Centro | F11: Residencial | I11: =IF(H11="","",IF(H11<=Preço!$C$7,Preço!$B$7,IF(H11<=Preço!$C$8,Preço!$B$8,IF(H11<=Preço!$C$9,Preço!$B$9,Preço!$B$10)))) | J11: =IF(H11="","",Preço!$D$7+MAX(0,MIN(H11,Preço!$C$8)-Preço!$C$7)*Preço!$D$8+MAX(0,MIN(H11,Preço!$C$9)-Preço!$C$8)*Preço!$D$9+MAX(0,H11-Preço!$C$9)*Preço!$D$10) | K11: =IF(H11="","",J11*12)
B12: 6 | C12: Condomínio Edifício Caiobá | D12: Rua Ceará, 712 | E12: Centro | F12: Residencial | I12: =IF(H12="","",IF(H12<=Preço!$C$7,Preço!$B$7,IF(H12<=Preço!$C$8,Preço!$B$8,IF(H12<=Preço!$C$9,Preço!$B$9,Preço!$B$10)))) | J12: =IF(H12="","",Preço!$D$7+MAX(0,MIN(H12,Preço!$C$8)-Preço!$C$7)*Preço!$D$8+MAX(0,MIN(H12,Preço!$C$9)-Preço!$C$8)*Preço!$D$9+MAX(0,H12-Preço!$C$9)*Preço!$D$10) | K12: =IF(H12="","",J12*12)
B13: 7 | C13: Condomínio Edifício Catanduva Center Comercial | D13: Rua Treze de Maio, 271 | E13: Centro | F13: Comercial / não residencial | I13: =IF(H13="","",IF(H13<=Preço!$C$7,Preço!$B$7,IF(H13<=Preço!$C$8,Preço!$B$8,IF(H13<=Preço!$C$9,Preço!$B$9,Preço!$B$10)))) | J13: =IF(H13="","",Preço!$D$7+MAX(0,MIN(H13,Preço!$C$8)-Preço!$C$7)*Preço!$D$8+MAX(0,MIN(H13,Preço!$C$9)-Preço!$C$8)*Preço!$D$9+MAX(0,H13-Preço!$C$9)*Preço!$D$10) | K13: =IF(H13="","",J13*12)
B14: 8 | C14: Condomínio Edifício Catanduva Shopping Center e Hotel | D14: Praça Monsenhor Albino, 114 | E14: Centro | F14: Comercial / não residencial | I14: =IF(H14="","",IF(H14<=Preço!$C$7,Preço!$B$7,IF(H14<=Preço!$C$8,Preço!$B$8,IF(H14<=Preço!$C$9,Preço!$B$9,Preço!$B$10)))) | J14: =IF(H14="","",Preço!$D$7+MAX(0,MIN(H14,Preço!$C$8)-Preço!$C$7)*Preço!$D$8+MAX(0,MIN(H14,Preço!$C$9)-Preço!$C$8)*Preço!$D$9+MAX(0,H14-Preço!$C$9)*Preço!$D$10) | K14: =IF(H14="","",J14*12)
B15: 9 | C15: Condomínio Edifício Comendador Elias Wady | D15: Rua Pernambuco, 267 | E15: Centro | F15: Residencial | I15: =IF(H15="","",IF(H15<=Preço!$C$7,Preço!$B$7,IF(H15<=Preço!$C$8,Preço!$B$8,IF(H15<=Preço!$C$9,Preço!$B$9,Preço!$B$10)))) | J15: =IF(H15="","",Preço!$D$7+MAX(0,MIN(H15,Preço!$C$8)-Preço!$C$7)*Preço!$D$8+MAX(0,MIN(H15,Preço!$C$9)-Preço!$C$8)*Preço!$D$9+MAX(0,H15-Preço!$C$9)*Preço!$D$10) | K15: =IF(H15="","",J15*12)
B16: 10 | C16: Condomínio Edifício Comercial Minas Center | D16: Rua 21 de Abril, 466 | E16: Centro | F16: Comercial / não residencial | I16: =IF(H16="","",IF(H16<=Preço!$C$7,Preço!$B$7,IF(H16<=Preço!$C$8,Preço!$B$8,IF(H16<=Preço!$C$9,Preço!$B$9,Preço!$B$10)))) | J16: =IF(H16="","",Preço!$D$7+MAX(0,MIN(H16,Preço!$C$8)-Preço!$C$7)*Preço!$D$8+MAX(0,MIN(H16,Preço!$C$9)-Preço!$C$8)*Preço!$D$9+MAX(0,H16-Preço!$C$9)*Preço!$D$10) | K16: =IF(H16="","",J16*12)
B17: 11 | C17: Condomínio Edifício Conjunto Residencial Ilhas Gregas | D17: Rua Sergipe, 609 | E17: Centro | F17: Residencial | I17: =IF(H17="","",IF(H17<=Preço!$C$7,Preço!$B$7,IF(H17<=Preço!$C$8,Preço!$B$8,IF(H17<=Preço!$C$9,Preço!$B$9,Preço!$B$10)))) | J17: =IF(H17="","",Preço!$D$7+MAX(0,MIN(H17,Preço!$C$8)-Preço!$C$7)*Preço!$D$8+MAX(0,MIN(H17,Preço!$C$9)-Preço!$C$8)*Preço!$D$9+MAX(0,H17-Preço!$C$9)*Preço!$D$10) | K17: =IF(H17="","",J17*12)
B18: 12 | C18: Condomínio Edifício Drogasil-Catanduva | D18: Rua Brasil, 648 | E18: Centro | F18: Comercial / não residencial | I18: =IF(H18="","",IF(H18<=Preço!$C$7,Preço!$B$7,IF(H18<=Preço!$C$8,Preço!$B$8,IF(H18<=Preço!$C$9,Preço!$B$9,Preço!$B$10)))) | J18: =IF(H18="","",Preço!$D$7+MAX(0,MIN(H18,Preço!$C$8)-Preço!$C$7)*Preço!$D$8+MAX(0,MIN(H18,Preço!$C$9)-Preço!$C$8)*Preço!$D$9+MAX(0,H18-Preço!$C$9)*Preço!$D$10) | K18: =IF(H18="","",J18*12)
... B22: 16 | C22: Condomínio Edifício Giselda | D22: Rua Minas Gerais, 155 | E22: Centro | F22: Residencial | I22: =IF(H22="","",IF(H22<=Preço!$C$7,Preço!$B$7,IF(H22<=Preço!$C$8,Preço!$B$8,IF(H22<=Preço!$C$9,Preço!$B$9,Preço!$B$10)))) | J22: =IF(H22="","",Preço!$D$7+MAX(0,MIN(H22,Preço!$C$8)-Preço!$C$7)*Preço!$D$8+MAX(0,MIN(H22,Preço!$C$9)-Preço!$C$8)*Preço!$D$9+MAX(0,H22-Preço!$C$9)*Preço!$D$10) | K22: =IF(H22="","",J22*12)
B23: 17 | C23: Condomínio Edifício Grão Pará | D23: Rua Pará, 353 | E23: Centro | F23: Residencial | G23: SIM | I23: =IF(H23="","",IF(H23<=Preço!$C$7,Preço!$B$7,IF(H23<=Preço!$C$8,Preço!$B$8,IF(H23<=Preço!$C$9,Preço!$B$9,Preço!$B$10)))) | J23: =IF(H23="","",Preço!$D$7+MAX(0,MIN(H23,Preço!$C$8)-Preço!$C$7)*Preço!$D$8+MAX(0,MIN(H23,Preço!$C$9)-Preço!$C$8)*Preço!$D$9+MAX(0,H23-Preço!$C$9)*Preço!$D$10) | K23: =IF(H23="","",J23*12)
B24: 18 | C24: Condomínio Edifício João Alonso Garcia | D24: Praça 9 de Julho, 131 | E24: Centro | F24: Residencial | I24: =IF(H24="","",IF(H24<=Preço!$C$7,Preço!$B$7,IF(H24<=Preço!$C$8,Preço!$B$8,IF(H24<=Preço!$C$9,Preço!$B$9,Preço!$B$10)))) | J24: =IF(H24="","",Preço!$D$7+MAX(0,MIN(H24,Preço!$C$8)-Preço!$C$7)*Preço!$D$8+MAX(0,MIN(H24,Preço!$C$9)-Preço!$C$8)*Preço!$D$9+MAX(0,H24-Preço!$C$9)*Preço!$D$10) | K24: =IF(H24="","",J24*12)
B25: 19 | C25: Condomínio Edifício Magoga | D25: Rua Alagoas, 411 | E25: Centro | F25: Residencial | I25: =IF(H25="","",IF(H25<=Preço!$C$7,Preço!$B$7,IF(H25<=Preço!$C$8,Preço!$B$8,IF(H25<=Preço!$C$9,Preço!$B$9,Preço!$B$10)))) | J25: =IF(H25="","",Preço!$D$7+MAX(0,MIN(H25,Preço!$C$8)-Preço!$C$7)*Preço!$D$8+MAX(0,MIN(H25,Preço!$C$9)-Preço!$C$8)*Preço!$D$9+MAX(0,H25-Preço!$C$9)*Preço!$D$10) | K25: =IF(H25="","",J25*12)
B26: 20 | C26: Condomínio Edifício Manaus | D26: Rua Manaus, 425 | E26: Centro | F26: Residencial | I26: =IF(H26="","",IF(H26<=Preço!$C$7,Preço!$B$7,IF(H26<=Preço!$C$8,Preço!$B$8,IF(H26<=Preço!$C$9,Preço!$B$9,Preço!$B$10)))) | J26: =IF(H26="","",Preço!$D$7+MAX(0,MIN(H26,Preço!$C$8)-Preço!$C$7)*Preço!$D$8+MAX(0,MIN(H26,Preço!$C$9)-Preço!$C$8)*Preço!$D$9+MAX(0,H26-Preço!$C$9)*Preço!$D$10) | K26: =IF(H26="","",J26*12)
B27: 21 | C27: Condomínio Edifício Marcílio Patriani | D27: Rua Pará, 433 | E27: Centro | F27: Residencial | I27: =IF(H27="","",IF(H27<=Preço!$C$7,Preço!$B$7,IF(H27<=Preço!$C$8,Preço!$B$8,IF(H27<=Preço!$C$9,Preço!$B$9,Preço!$B$10)))) | J27: =IF(H27="","",Preço!$D$7+MAX(0,MIN(H27,Preço!$C$8)-Preço!$C$7)*Preço!$D$8+MAX(0,MIN(H27,Preço!$C$9)-Preço!$C$8)*Preço!$D$9+MAX(0,H27-Preço!$C$9)*Preço!$D$10) | K27: =IF(H27="","",J27*12)
B28: 22 | C28: Condomínio Edifício Mediterrâneo | D28: Rua Bahia, 27 | E28: Centro | F28: Residencial | I28: =IF(H28="","",IF(H28<=Preço!$C$7,Preço!$B$7,IF(H28<=Preço!$C$8,Preço!$B$8,IF(H28<=Preço!$C$9,Preço!$B$9,Preço!$B$10)))) | J28: =IF(H28="","",Preço!$D$7+MAX(0,MIN(H28,Preço!$C$8)-Preço!$C$7)*Preço!$D$8+MAX(0,MIN(H28,Preço!$C$9)-Preço!$C$8)*Preço!$D$9+MAX(0,H28-Preço!$C$9)*Preço!$D$10) | K28: =IF(H28="","",J28*12)
B29: 23 | C29: Condomínio Edifício Monsenhor Albino | D29: Rua Bahia, 55 | E29: Centro | F29: Residencial | I29: =IF(H29="","",IF(H29<=Preço!$C$7,Preço!$B$7,IF(H29<=Preço!$C$8,Preço!$B$8,IF(H29<=Preço!$C$9,Preço!$B$9,Preço!$B$10)))) | J29: =IF(H29="","",Preço!$D$7+MAX(0,MIN(H29,Preço!$C$8)-Preço!$C$7)*Preço!$D$8+MAX(0,MIN(H29,Preço!$C$9)-Preço!$C$8)*Preço!$D$9+MAX(0,H29-Preço!$C$9)*Preço!$D$10) | K29: =IF(H29="","",J29*12)
B30: 24 | C30: Condomínio Edifício Professor Raul do Prado Vianna | D30: Rua Ceará, 527 | E30: Centro | F30: Residencial | I30: =IF(H30="","",IF(H30<=Preço!$C$7,Preço!$B$7,IF(H30<=Preço!$C$8,Preço!$B$8,IF(H30<=Preço!$C$9,Preço!$B$9,Preço!$B$10)))) | J30: =IF(H30="","",Preço!$D$7+MAX(0,MIN(H30,Preço!$C$8)-Preço!$C$7)*Preço!$D$8+MAX(0,MIN(H30,Preço!$C$9)-Preço!$C$8)*Preço!$D$9+MAX(0,H30-Preço!$C$9)*Preço!$D$10) | K30: =IF(H30="","",J30*12)
B31: 25 | C31: Condomínio Edifício Renato Ribeiro | D31: Rua Aracaju, 381 | E31: Centro | F31: Residencial | I31: =IF(H31="","",IF(H31<=Preço!$C$7,Preço!$B$7,IF(H31<=Preço!$C$8,Preço!$B$8,IF(H31<=Preço!$C$9,Preço!$B$9,Preço!$B$10)))) | J31: =IF(H31="","",Preço!$D$7+MAX(0,MIN(H31,Preço!$C$8)-Preço!$C$7)*Preço!$D$8+MAX(0,MIN(H31,Preço!$C$9)-Preço!$C$8)*Preço!$D$9+MAX(0,H31-Preço!$C$9)*Preço!$D$10) | K31: =IF(H31="","",J31*12)
B32: 26 | C32: Condomínio Edifício Residencial Acapulco | D32: Rua Bahia, 521 | E32: Centro | F32: Residencial | I32: =IF(H32="","",IF(H32<=Preço!$C$7,Preço!$B$7,IF(H32<=Preço!$C$8,Preço!$B$8,IF(H32<=Preço!$C$9,Preço!$B$9,Preço!$B$10)))) | J32: =IF(H32="","",Preço!$D$7+MAX(0,MIN(H32,Preço!$C$8)-Preço!$C$7)*Preço!$D$8+MAX(0,MIN(H32,Preço!$C$9)-Preço!$C$8)*Preço!$D$9+MAX(0,H32-Preço!$C$9)*Preço!$D$10) | K32: =IF(H32="","",J32*12)
B33: 27 | C33: Condomínio Edifício Residencial Antônio Dispore | D33: Rua Recife, 585 | E33: Centro | F33: Residencial | I33: =IF(H33="","",IF(H33<=Preço!$C$7,Preço!$B$7,IF(H33<=Preço!$C$8,Preço!$B$8,IF(H33<=Preço!$C$9,Preço!$B$9,Preço!$B$10)))) | J33: =IF(H33="","",Preço!$D$7+MAX(0,MIN(H33,Preço!$C$8)-Preço!$C$7)*Preço!$D$8+MAX(0,MIN(H33,Preço!$C$9)-Preço!$C$8)*Preço!$D$9+MAX(0,H33-Preço!$C$9)*Preço!$D$10) | K33: =IF(H33="","",J33*12)
B34: 28 | C34: Condomínio Edifício Residencial Barcelona | D34: Rua Ceará, 550 | E34: Centro | F34: Residencial | I34: =IF(H34="","",IF(H34<=Preço!$C$7,Preço!$B$7,IF(H34<=Preço!$C$8,Preço!$B$8,IF(H34<=Preço!$C$9,Preço!$B$9,Preço!$B$10)))) | J34: =IF(H34="","",Preço!$D$7+MAX(0,MIN(H34,Preço!$C$8)-Preço!$C$7)*Preço!$D$8+MAX(0,MIN(H34,Preço!$C$9)-Preço!$C$8)*Preço!$D$9+MAX(0,H34-Preço!$C$9)*Preço!$D$10) | K34: =IF(H34="","",J34*12)
B35: 29 | C35: Condomínio Edifício Residencial Fabiano Ramos | D35: Rua Maranhão, 1560 | E35: Centro | F35: Residencial | I35: =IF(H35="","",IF(H35<=Preço!$C$7,Preço!$B$7,IF(H35<=Preço!$C$8,Preço!$B$8,IF(H35<=Preço!$C$9,Preço!$B$9,Preço!$B$10)))) | J35: =IF(H35="","",Preço!$D$7+MAX(0,MIN(H35,Preço!$C$8)-Preço!$C$7)*Preço!$D$8+MAX(0,MIN(H35,Preço!$C$9)-Preço!$C$8)*Preço!$D$9+MAX(0,H35-Preço!$C$9)*Preço!$D$10) | K35: =IF(H35="","",J35*12)
... B41: 35 | C41: Condomínio Edifício Residencial Veneza | D41: Rua Amazonas, 290 | E41: Centro | F41: Residencial | I41: =IF(H41="","",IF(H41<=Preço!$C$7,Preço!$B$7,IF(H41<=Preço!$C$8,Preço!$B$8,IF(H41<=Preço!$C$9,Preço!$B$9,Preço!$B$10)))) | J41: =IF(H41="","",Preço!$D$7+MAX(0,MIN(H41,Preço!$C$8)-Preço!$C$7)*Preço!$D$8+MAX(0,MIN(H41,Preço!$C$9)-Preço!$C$8)*Preço!$D$9+MAX(0,H41-Preço!$C$9)*Preço!$D$10) | K41: =IF(H41="","",J41*12)
B42: 36 | C42: Condomínio Edifício Rio Negro | D42: Rua Belém, 15 | E42: Centro | F42: Residencial | G42: SIM | I42: =IF(H42="","",IF(H42<=Preço!$C$7,Preço!$B$7,IF(H42<=Preço!$C$8,Preço!$B$8,IF(H42<=Preço!$C$9,Preço!$B$9,Preço!$B$10)))) | J42: =IF(H42="","",Preço!$D$7+MAX(0,MIN(H42,Preço!$C$8)-Preço!$C$7)*Preço!$D$8+MAX(0,MIN(H42,Preço!$C$9)-Preço!$C$8)*Preço!$D$9+MAX(0,H42-Preço!$C$9)*Preço!$D$10) | K42: =IF(H42="","",J42*12)
B43: 37 | C43: Condomínio Edifício Roque Barba | D43: Rua 13 de Maio, 341 | E43: Centro | F43: Residencial | I43: =IF(H43="","",IF(H43<=Preço!$C$7,Preço!$B$7,IF(H43<=Preço!$C$8,Preço!$B$8,IF(H43<=Preço!$C$9,Preço!$B$9,Preço!$B$10)))) | J43: =IF(H43="","",Preço!$D$7+MAX(0,MIN(H43,Preço!$C$8)-Preço!$C$7)*Preço!$D$8+MAX(0,MIN(H43,Preço!$C$9)-Preço!$C$8)*Preço!$D$9+MAX(0,H43-Preço!$C$9)*Preço!$D$10) | K43: =IF(H43="","",J43*12)
B44: 38 | C44: Condomínio Edifício Santa Cruz | D44: Rua Aracaju, 390 | E44: Centro | F44: Residencial | I44: =IF(H44="","",IF(H44<=Preço!$C$7,Preço!$B$7,IF(H44<=Preço!$C$8,Preço!$B$8,IF(H44<=Preço!$C$9,Preço!$B$9,Preço!$B$10)))) | J44: =IF(H44="","",Preço!$D$7+MAX(0,MIN(H44,Preço!$C$8)-Preço!$C$7)*Preço!$D$8+MAX(0,MIN(H44,Preço!$C$9)-Preço!$C$8)*Preço!$D$9+MAX(0,H44-Preço!$C$9)*Preço!$D$10) | K44: =IF(H44="","",J44*12)
B45: 39 | C45: Condomínio Edifício Shangri-La | D45: Rua Aracaju, 545 | E45: Centro | F45: Residencial | I45: =IF(H45="","",IF(H45<=Preço!$C$7,Preço!$B$7,IF(H45<=Preço!$C$8,Preço!$B$8,IF(H45<=Preço!$C$9,Preço!$B$9,Preço!$B$10)))) | J45: =IF(H45="","",Preço!$D$7+MAX(0,MIN(H45,Preço!$C$8)-Preço!$C$7)*Preço!$D$8+MAX(0,MIN(H45,Preço!$C$9)-Preço!$C$8)*Preço!$D$9+MAX(0,H45-Preço!$C$9)*Preço!$D$10) | K45: =IF(H45="","",J45*12)
B46: 40 | C46: Condomínio Edifício Veredas do Sol | D46: Rua Alagoas, 724 | E46: Centro | F46: Residencial | G46: SIM | I46: =IF(H46="","",IF(H46<=Preço!$C$7,Preço!$B$7,IF(H46<=Preço!$C$8,Preço!$B$8,IF(H46<=Preço!$C$9,Preço!$B$9,Preço!$B$10)))) | J46: =IF(H46="","",Preço!$D$7+MAX(0,MIN(H46,Preço!$C$8)-Preço!$C$7)*Preço!$D$8+MAX(0,MIN(H46,Preço!$C$9)-Preço!$C$8)*Preço!$D$9+MAX(0,H46-Preço!$C$9)*Preço!$D$10) | K46: =IF(H46="","",J46*12)
B47: 41 | C47: Condomínio Edifício do Café | D47: Praça da República, 6 | E47: Centro | F47: Residencial | I47: =IF(H47="","",IF(H47<=Preço!$C$7,Preço!$B$7,IF(H47<=Preço!$C$8,Preço!$B$8,IF(H47<=Preço!$C$9,Preço!$B$9,Preço!$B$10)))) | J47: =IF(H47="","",Preço!$D$7+MAX(0,MIN(H47,Preço!$C$8)-Preço!$C$7)*Preço!$D$8+MAX(0,MIN(H47,Preço!$C$9)-Preço!$C$8)*Preço!$D$9+MAX(0,H47-Preço!$C$9)*Preço!$D$10) | K47: =IF(H47="","",J47*12)
B48: 42 | C48: Condomínio Edifício Ângela Mastrocola | D48: Praça da República, 120 | E48: Centro | F48: Residencial | I48: =IF(H48="","",IF(H48<=Preço!$C$7,Preço!$B$7,IF(H48<=Preço!$C$8,Preço!$B$8,IF(H48<=Preço!$C$9,Preço!$B$9,Preço!$B$10)))) | J48: =IF(H48="","",Preço!$D$7+MAX(0,MIN(H48,Preço!$C$8)-Preço!$C$7)*Preço!$D$8+MAX(0,MIN(H48,Preço!$C$9)-Preço!$C$8)*Preço!$D$9+MAX(0,H48-Preço!$C$9)*Preço!$D$10) | K48: =IF(H48="","",J48*12)
B49: 43 | C49: Condomínio Residencial Antônio Simieli | D49: Rua Minas Gerais, 180 | E49: Centro | F49: Residencial | I49: =IF(H49="","",IF(H49<=Preço!$C$7,Preço!$B$7,IF(H49<=Preço!$C$8,Preço!$B$8,IF(H49<=Preço!$C$9,Preço!$B$9,Preço!$B$10)))) | J49: =IF(H49="","",Preço!$D$7+MAX(0,MIN(H49,Preço!$C$8)-Preço!$C$7)*Preço!$D$8+MAX(0,MIN(H49,Preço!$C$9)-Preço!$C$8)*Preço!$D$9+MAX(0,H49-Preço!$C$9)*Preço!$D$10) | K49: =IF(H49="","",J49*12)
B50: 44 | C50: Condomínio Residencial Aurélio Righini | D50: Rua Treze de Maio, 1779 | E50: Centro | F50: Residencial | I50: =IF(H50="","",IF(H50<=Preço!$C$7,Preço!$B$7,IF(H50<=Preço!$C$8,Preço!$B$8,IF(H50<=Preço!$C$9,Preço!$B$9,Preço!$B$10)))) | J50: =IF(H50="","",Preço!$D$7+MAX(0,MIN(H50,Preço!$C$8)-Preço!$C$7)*Preço!$D$8+MAX(0,MIN(H50,Preço!$C$9)-Preço!$C$8)*Preço!$D$9+MAX(0,H50-Preço!$C$9)*Preço!$D$10) | K50: =IF(H50="","",J50*12)
B51: 45 | C51: Condomínio Residencial Bahia | D51: Rua Bahia, 1303 | E51: Centro | F51: Residencial | I51: =IF(H51="","",IF(H51<=Preço!$C$7,Preço!$B$7,IF(H51<=Preço!$C$8,Preço!$B$8,IF(H51<=Preço!$C$9,Preço!$B$9,Preço!$B$10)))) | J51: =IF(H51="","",Preço!$D$7+MAX(0,MIN(H51,Preço!$C$8)-Preço!$C$7)*Preço!$D$8+MAX(0,MIN(H51,Preço!$C$9)-Preço!$C$8)*Preço!$D$9+MAX(0,H51-Preço!$C$9)*Preço!$D$10) | K51: =IF(H51="","",J51*12)
...

Sheet Preço
B2: Tabela de preço por zonas
B3: Edite só o amarelo. Alimenta o cálculo da aba anterior.
B6: Faixa | C6: Limite superior | D6: Valor | E6: Unidades
B7: Compacto | C7: 30 | D7: 298 | E7: Até 30 unidades
B8: Padrão | C8: 60 | D8: 9.9 | E8: Da 31ª à 60ª
B9: Plus | C9: 120 | D9: 8.9 | E9: Da 61ª à 120ª
B10: Corporativo | C10: — | D10: 11.9 | E10: Acima da 120ª
B12: Taxa de implantação (única) | D12: 490

Sheet Fontes e método
B2: De onde vieram estes dados e o que ainda falta
B3: Leia antes de sair ligando.
B5: O QUE ESTÁ CONFIRMADO
B6: Nome, endereço e bairro dos condomínios: extraídos do diretório Solutudo, categoria "Condomínios - Edifícios" de Catanduva/SP, que declara 118 empresas cadastradas nessa categoria. Foram removidas as duplicidades por endereço. O Vista Impper veio de notícia do Grupo Impper (160 unidades, 20 pavimentos).
B8: Confiança na lista: alta para existência do condomínio, média para grafia do nome e número do endereço, porque diretórios têm cadastro desatualizado. Confirme o endereço antes de ir até o prédio.
B11: O QUE NÃO ESTÁ CONFIRMADO — E POR QUÊ
B12: O NÚMERO DE UNIDADES não é publicado em nenhuma fonte aberta. Nem diretório, nem prefeitura, nem cartório disponibilizam isso on-line. Por isso a coluna Unidades está vazia e amarela: é o único dado que você precisa levantar, e é justamente o que define o preço.
B14: Três formas rápidas de conseguir: (1) Google Maps em Street View — conte os andares e as janelas por andar, dá uma estimativa boa em 30 segundos por prédio; (2) anúncios de venda do prédio costumam citar "apto X de Y"; (3) pergunte ao porteiro — leva 10 segundos e vem com o nome do síndico de brinde.
B17: O QUE A LISTA REVELA
B18: A esmagadora maioria dos verticais está no CENTRO e na HIGIENÓPOLIS. Se você tiver uma tarde, é ali que ela rende mais. Parque Iracema, São Francisco e Jardim Santa Helena vêm em seguida.
B20: Alguns registros são comerciais, não residenciais (Minas Center, Catanduva Shopping Center, Drogasil, Conjunto Esportivo João Crippa). Estão marcados na coluna Tipo — não descarte de imediato: prédio comercial também tem síndico, portaria e encomenda.
B22: Doze condomínios da lista já são seus clientes e estão marcados em verde na coluna "Já é cliente?". Damha, Ideal Life e Santa Andélia não aparecem no diretório — provavelmente porque são horizontais ou estão cadastrados com outra razão social.
... B32: Casa dos Dados — CNPJ de condomínios de Catanduva (Idalina C. Kaiser, Catuaí): casadosdados.com.br
