Workbook

Sheet Lista de ligação
B2: Lista de ligação — 70 condomínios para contatar
B3: Ordem sugerida: quem tem telefone confiável primeiro. Preencha as colunas amarelas durante a ligação.
B6: # | C6: Condomínio | D6: Bairro | E6: Endereço | F6: Telefone da portaria | G6: Atenção no telefone | H6: Data do contato | I6: Falou com | J6: Nome do síndico | K6: Telefone do síndico | L6: Unidades | M6: Já tem app de controle de acesso? | N6: Qual app | O6: Interesse | P6: Próximo passo | Q6: Faixa | R6: Mensalidade | S6: Observações
B7: 1 | C7: Condomínio Edifício Alagoas | D7: Centro | E7: Rua Alagoas, 340 | F7: (17) 3522-9571 | Q7: =IF(L7="","",IF(L7<=Preço!$C$7,Preço!$B$7,IF(L7<=Preço!$C$8,Preço!$B$8,IF(L7<=Preço!$C$9,Preço!$B$9,Preço!$B$10)))) | R7: =IF(L7="","",Preço!$D$7+MAX(0,MIN(L7,Preço!$C$8)-Preço!$C$7)*Preço!$D$8+MAX(0,MIN(L7,Preço!$C$9)-Preço!$C$8)*Preço!$D$9+MAX(0,L7-Preço!$C$9)*Preço!$D$10)
B8: 2 | C8: Condomínio Edifício Arnaldo Bittencourt | D8: Centro | E8: Rua Sergipe, 197 | F8: (17) 3522-4176 | Q8: =IF(L8="","",IF(L8<=Preço!$C$7,Preço!$B$7,IF(L8<=Preço!$C$8,Preço!$B$8,IF(L8<=Preço!$C$9,Preço!$B$9,Preço!$B$10)))) | R8: =IF(L8="","",Preço!$D$7+MAX(0,MIN(L8,Preço!$C$8)-Preço!$C$7)*Preço!$D$8+MAX(0,MIN(L8,Preço!$C$9)-Preço!$C$8)*Preço!$D$9+MAX(0,L8-Preço!$C$9)*Preço!$D$10)
B9: 3 | C9: Condomínio Edifício Esther | D9: Centro | E9: Rua Bahia, 143 | F9: (17) 3522-7936 | Q9: =IF(L9="","",IF(L9<=Preço!$C$7,Preço!$B$7,IF(L9<=Preço!$C$8,Preço!$B$8,IF(L9<=Preço!$C$9,Preço!$B$9,Preço!$B$10)))) | R9: =IF(L9="","",Preço!$D$7+MAX(0,MIN(L9,Preço!$C$8)-Preço!$C$7)*Preço!$D$8+MAX(0,MIN(L9,Preço!$C$9)-Preço!$C$8)*Preço!$D$9+MAX(0,L9-Preço!$C$9)*Preço!$D$10)
B10: 4 | C10: Condomínio Edifício Floriano Lima | D10: Centro | E10: Rua Mogi Mirim, 63 | F10: (17) 3522-4104 | Q10: =IF(L10="","",IF(L10<=Preço!$C$7,Preço!$B$7,IF(L10<=Preço!$C$8,Preço!$B$8,IF(L10<=Preço!$C$9,Preço!$B$9,Preço!$B$10)))) | R10: =IF(L10="","",Preço!$D$7+MAX(0,MIN(L10,Preço!$C$8)-Preço!$C$7)*Preço!$D$8+MAX(0,MIN(L10,Preço!$C$9)-Preço!$C$8)*Preço!$D$9+MAX(0,L10-Preço!$C$9)*Preço!$D$10)
B11: 5 | C11: Condomínio Edifício Giselda | D11: Centro | E11: Rua Minas Gerais, 155 | F11: (17) 3523-2339 | Q11: =IF(L11="","",IF(L11<=Preço!$C$7,Preço!$B$7,IF(L11<=Preço!$C$8,Preço!$B$8,IF(L11<=Preço!$C$9,Preço!$B$9,Preço!$B$10)))) | R11: =IF(L11="","",Preço!$D$7+MAX(0,MIN(L11,Preço!$C$8)-Preço!$C$7)*Preço!$D$8+MAX(0,MIN(L11,Preço!$C$9)-Preço!$C$8)*Preço!$D$9+MAX(0,L11-Preço!$C$9)*Preço!$D$10)
B12: 6 | C12: Condomínio Edifício Marcílio Patriani | D12: Centro | E12: Rua Pará, 433 | F12: (17) 3523-7732 | Q12: =IF(L12="","",IF(L12<=Preço!$C$7,Preço!$B$7,IF(L12<=Preço!$C$8,Preço!$B$8,IF(L12<=Preço!$C$9,Preço!$B$9,Preço!$B$10)))) | R12: =IF(L12="","",Preço!$D$7+MAX(0,MIN(L12,Preço!$C$8)-Preço!$C$7)*Preço!$D$8+MAX(0,MIN(L12,Preço!$C$9)-Preço!$C$8)*Preço!$D$9+MAX(0,L12-Preço!$C$9)*Preço!$D$10)
B13: 7 | C13: Condomínio Edifício Monsenhor Albino | D13: Centro | E13: Rua Bahia, 55 | F13: (17) 3523-2342 | Q13: =IF(L13="","",IF(L13<=Preço!$C$7,Preço!$B$7,IF(L13<=Preço!$C$8,Preço!$B$8,IF(L13<=Preço!$C$9,Preço!$B$9,Preço!$B$10)))) | R13: =IF(L13="","",Preço!$D$7+MAX(0,MIN(L13,Preço!$C$8)-Preço!$C$7)*Preço!$D$8+MAX(0,MIN(L13,Preço!$C$9)-Preço!$C$8)*Preço!$D$9+MAX(0,L13-Preço!$C$9)*Preço!$D$10)
B14: 8 | C14: Condomínio Edifício Pedro Magoga | D14: Centro | E14: R. Alagoas, 411 | F14: (17) 3524-6012 | Q14: =IF(L14="","",IF(L14<=Preço!$C$7,Preço!$B$7,IF(L14<=Preço!$C$8,Preço!$B$8,IF(L14<=Preço!$C$9,Preço!$B$9,Preço!$B$10)))) | R14: =IF(L14="","",Preço!$D$7+MAX(0,MIN(L14,Preço!$C$8)-Preço!$C$7)*Preço!$D$8+MAX(0,MIN(L14,Preço!$C$9)-Preço!$C$8)*Preço!$D$9+MAX(0,L14-Preço!$C$9)*Preço!$D$10)
B15: 9 | C15: Condomínio Edifício Residencial Barcelona | D15: Centro | E15: Rua Ceará, 550 | F15: (17) 3522-0699 | Q15: =IF(L15="","",IF(L15<=Preço!$C$7,Preço!$B$7,IF(L15<=Preço!$C$8,Preço!$B$8,IF(L15<=Preço!$C$9,Preço!$B$9,Preço!$B$10)))) | R15: =IF(L15="","",Preço!$D$7+MAX(0,MIN(L15,Preço!$C$8)-Preço!$C$7)*Preço!$D$8+MAX(0,MIN(L15,Preço!$C$9)-Preço!$C$8)*Preço!$D$9+MAX(0,L15-Preço!$C$9)*Preço!$D$10)
B16: 10 | C16: Condomínio Edifício Residencial Higino Gradella | D16: Centro | E16: Rua Teresina, 842 | F16: (17) 3522-5000 | Q16: =IF(L16="","",IF(L16<=Preço!$C$7,Preço!$B$7,IF(L16<=Preço!$C$8,Preço!$B$8,IF(L16<=Preço!$C$9,Preço!$B$9,Preço!$B$10)))) | R16: =IF(L16="","",Preço!$D$7+MAX(0,MIN(L16,Preço!$C$8)-Preço!$C$7)*Preço!$D$8+MAX(0,MIN(L16,Preço!$C$9)-Preço!$C$8)*Preço!$D$9+MAX(0,L16-Preço!$C$9)*Preço!$D$10)
B17: 11 | C17: Condomínio Edifício Residencial Marieta Zancaner | D17: Centro | E17: Rua Alagoas, 341 | F17: (17) 3522-8622 | Q17: =IF(L17="","",IF(L17<=Preço!$C$7,Preço!$B$7,IF(L17<=Preço!$C$8,Preço!$B$8,IF(L17<=Preço!$C$9,Preço!$B$9,Preço!$B$10)))) | R17: =IF(L17="","",Preço!$D$7+MAX(0,MIN(L17,Preço!$C$8)-Preço!$C$7)*Preço!$D$8+MAX(0,MIN(L17,Preço!$C$9)-Preço!$C$8)*Preço!$D$9+MAX(0,L17-Preço!$C$9)*Preço!$D$10)
B18: 12 | C18: Condomínio Edifício Roque Barba | D18: Centro | E18: Rua 13 de Maio, 341 | F18: (17) 3522-6384 | Q18: =IF(L18="","",IF(L18<=Preço!$C$7,Preço!$B$7,IF(L18<=Preço!$C$8,Preço!$B$8,IF(L18<=Preço!$C$9,Preço!$B$9,Preço!$B$10)))) | R18: =IF(L18="","",Preço!$D$7+MAX(0,MIN(L18,Preço!$C$8)-Preço!$C$7)*Preço!$D$8+MAX(0,MIN(L18,Preço!$C$9)-Preço!$C$8)*Preço!$D$9+MAX(0,L18-Preço!$C$9)*Preço!$D$10)
... B40: 34 | C40: Condomínio Edifício Residencial Petrópolis | D40: São Francisco | E40: Rua Petrópolis, 100 | F40: (17) 99709-4492 | Q40: =IF(L40="","",IF(L40<=Preço!$C$7,Preço!$B$7,IF(L40<=Preço!$C$8,Preço!$B$8,IF(L40<=Preço!$C$9,Preço!$B$9,Preço!$B$10)))) | R40: =IF(L40="","",Preço!$D$7+MAX(0,MIN(L40,Preço!$C$8)-Preço!$C$7)*Preço!$D$8+MAX(0,MIN(L40,Preço!$C$9)-Preço!$C$8)*Preço!$D$9+MAX(0,L40-Preço!$C$9)*Preço!$D$10)
B41: 35 | C41: Condomínio Edifício Prof. Raul do Prado Vianna | F41: (17) 3523-1015 | Q41: =IF(L41="","",IF(L41<=Preço!$C$7,Preço!$B$7,IF(L41<=Preço!$C$8,Preço!$B$8,IF(L41<=Preço!$C$9,Preço!$B$9,Preço!$B$10)))) | R41: =IF(L41="","",Preço!$D$7+MAX(0,MIN(L41,Preço!$C$8)-Preço!$C$7)*Preço!$D$8+MAX(0,MIN(L41,Preço!$C$9)-Preço!$C$8)*Preço!$D$9+MAX(0,L41-Preço!$C$9)*Preço!$D$10)
B42: 36 | C42: Condomínio Edifício Residencial Veneza | D42:  | E42: Rua Amazonas, 290 | F42: (17) 3522-8803 | Q42: =IF(L42="","",IF(L42<=Preço!$C$7,Preço!$B$7,IF(L42<=Preço!$C$8,Preço!$B$8,IF(L42<=Preço!$C$9,Preço!$B$9,Preço!$B$10)))) | R42: =IF(L42="","",Preço!$D$7+MAX(0,MIN(L42,Preço!$C$8)-Preço!$C$7)*Preço!$D$8+MAX(0,MIN(L42,Preço!$C$9)-Preço!$C$8)*Preço!$D$9+MAX(0,L42-Preço!$C$9)*Preço!$D$10)
B43: 37 | C43: Condomínio Edifício Amazonas | D43: Centro | E43: Rua Minas Gerais, 106 | F43: (17) 3522-4223 | G43: Telefone repetido em: Condomínio Edifício Manaus | Q43: =IF(L43="","",IF(L43<=Preço!$C$7,Preço!$B$7,IF(L43<=Preço!$C$8,Preço!$B$8,IF(L43<=Preço!$C$9,Preço!$B$9,Preço!$B$10)))) | R43: =IF(L43="","",Preço!$D$7+MAX(0,MIN(L43,Preço!$C$8)-Preço!$C$7)*Preço!$D$8+MAX(0,MIN(L43,Preço!$C$9)-Preço!$C$8)*Preço!$D$9+MAX(0,L43-Preço!$C$9)*Preço!$D$10)
B44: 38 | C44: Condomínio Edifício Bahia | D44: Centro | E44: Rua Bahia, 321 | F44: (17) 3045-3650 | G44: Telefone repetido em: Condomínio Residencial Bahia | Q44: =IF(L44="","",IF(L44<=Preço!$C$7,Preço!$B$7,IF(L44<=Preço!$C$8,Preço!$B$8,IF(L44<=Preço!$C$9,Preço!$B$9,Preço!$B$10)))) | R44: =IF(L44="","",Preço!$D$7+MAX(0,MIN(L44,Preço!$C$8)-Preço!$C$7)*Preço!$D$8+MAX(0,MIN(L44,Preço!$C$9)-Preço!$C$8)*Preço!$D$9+MAX(0,L44-Preço!$C$9)*Preço!$D$10)
B45: 39 | C45: Condomínio Edifício João Alonso Garcia | D45: Centro | E45: Praça 9 de Julho, 131 | F45: (17) 3521-7019 | G45: Telefone repetido em: Condomínio Edifício Residencial Antônio Alonso Garcia | Q45: =IF(L45="","",IF(L45<=Preço!$C$7,Preço!$B$7,IF(L45<=Preço!$C$8,Preço!$B$8,IF(L45<=Preço!$C$9,Preço!$B$9,Preço!$B$10)))) | R45: =IF(L45="","",Preço!$D$7+MAX(0,MIN(L45,Preço!$C$8)-Preço!$C$7)*Preço!$D$8+MAX(0,MIN(L45,Preço!$C$9)-Preço!$C$8)*Preço!$D$9+MAX(0,L45-Preço!$C$9)*Preço!$D$10)
B46: 40 | C46: Condomínio Residencial Bahia | D46: Centro | E46: Rua Bahia, 321 | F46: (17) 3045-3650 | G46: Telefone repetido em: Condomínio Edifício Bahia | Q46: =IF(L46="","",IF(L46<=Preço!$C$7,Preço!$B$7,IF(L46<=Preço!$C$8,Preço!$B$8,IF(L46<=Preço!$C$9,Preço!$B$9,Preço!$B$10)))) | R46: =IF(L46="","",Preço!$D$7+MAX(0,MIN(L46,Preço!$C$8)-Preço!$C$7)*Preço!$D$8+MAX(0,MIN(L46,Preço!$C$9)-Preço!$C$8)*Preço!$D$9+MAX(0,L46-Preço!$C$9)*Preço!$D$10)
B47: 41 | C47: Edifício Engenheiro José Nelson Machado | D47: Centro | E47: Praça da República, 145 | F47: (11) 4020-2208 | G47: DDD 11 — Catanduva é DDD 17 | Q47: =IF(L47="","",IF(L47<=Preço!$C$7,Preço!$B$7,IF(L47<=Preço!$C$8,Preço!$B$8,IF(L47<=Preço!$C$9,Preço!$B$9,Preço!$B$10)))) | R47: =IF(L47="","",Preço!$D$7+MAX(0,MIN(L47,Preço!$C$8)-Preço!$C$7)*Preço!$D$8+MAX(0,MIN(L47,Preço!$C$9)-Preço!$C$8)*Preço!$D$9+MAX(0,L47-Preço!$C$9)*Preço!$D$10)
B48: 42 | C48: Edifício Residencial Alvorada | D48: Centro | E48: Rua Ceará, 859 | F48: (17) 3522-1257 | G48: Telefone repetido em: Residencial Jardim Alvorada; Condomínio Residencial Flamboyant | Q48: =IF(L48="","",IF(L48<=Preço!$C$7,Preço!$B$7,IF(L48<=Preço!$C$8,Preço!$B$8,IF(L48<=Preço!$C$9,Preço!$B$9,Preço!$B$10)))) | R48: =IF(L48="","",Preço!$D$7+MAX(0,MIN(L48,Preço!$C$8)-Preço!$C$7)*Preço!$D$8+MAX(0,MIN(L48,Preço!$C$9)-Preço!$C$8)*Preço!$D$9+MAX(0,L48-Preço!$C$9)*Preço!$D$10)
B49: 43 | C49: Condomínio Residencial Flamboyant | D49: Conj. Hab. Pref. João Righini | E49: Rua Atibaia, 90 | F49: (17) 3522-1257 | G49: Telefone repetido em: Residencial Jardim Alvorada; Edifício Residencial Alvorada | Q49: =IF(L49="","",IF(L49<=Preço!$C$7,Preço!$B$7,IF(L49<=Preço!$C$8,Preço!$B$8,IF(L49<=Preço!$C$9,Preço!$B$9,Preço!$B$10)))) | R49: =IF(L49="","",Preço!$D$7+MAX(0,MIN(L49,Preço!$C$8)-Preço!$C$7)*Preço!$D$8+MAX(0,MIN(L49,Preço!$C$9)-Preço!$C$8)*Preço!$D$9+MAX(0,L49-Preço!$C$9)*Preço!$D$10)
B50: 44 | C50: Condomínio Edifício Residencial Antônio Alonso Garcia | D50: Higienópolis | E50: Rua Mato Grosso, 585 | F50: (17) 3521-7019 | G50: Telefone repetido em: Condomínio Edifício João Alonso Garcia | Q50: =IF(L50="","",IF(L50<=Preço!$C$7,Preço!$B$7,IF(L50<=Preço!$C$8,Preço!$B$8,IF(L50<=Preço!$C$9,Preço!$B$9,Preço!$B$10)))) | R50: =IF(L50="","",Preço!$D$7+MAX(0,MIN(L50,Preço!$C$8)-Preço!$C$7)*Preço!$D$8+MAX(0,MIN(L50,Preço!$C$9)-Preço!$C$8)*Preço!$D$9+MAX(0,L50-Preço!$C$9)*Preço!$D$10)
B51: 45 | C51: Condomínio Residencial Gabriela | D51: Jardim Belém | E51: Rua São Carlos, 1117 | F51: (17) 523-5719 | G51: Só 7 dígitos após o DDD — número incompleto | Q51: =IF(L51="","",IF(L51<=Preço!$C$7,Preço!$B$7,IF(L51<=Preço!$C$8,Preço!$B$8,IF(L51<=Preço!$C$9,Preço!$B$9,Preço!$B$10)))) | R51: =IF(L51="","",Preço!$D$7+MAX(0,MIN(L51,Preço!$C$8)-Preço!$C$7)*Preço!$D$8+MAX(0,MIN(L51,Preço!$C$9)-Preço!$C$8)*Preço!$D$9+MAX(0,L51-Preço!$C$9)*Preço!$D$10)
B52: 46 | C52: Condomínio Residencial Paineiras | D52: Nações Unidas | E52: Rua José Frias Garcia, 510 | F52: (17) 9724-9546 | G52: Celular sem o 9 — provavelmente falta um dígito | Q52: =IF(L52="","",IF(L52<=Preço!$C$7,Preço!$B$7,IF(L52<=Preço!$C$8,Preço!$B$8,IF(L52<=Preço!$C$9,Preço!$B$9,Preço!$B$10)))) | R52: =IF(L52="","",Preço!$D$7+MAX(0,MIN(L52,Preço!$C$8)-Preço!$C$7)*Preço!$D$8+MAX(0,MIN(L52,Preço!$C$9)-Preço!$C$8)*Preço!$D$9+MAX(0,L52-Preço!$C$9)*Preço!$D$10)
B53: 47 | C53: Condomínio Edifício Gaivotas | D53: Parque Iracema | E53: Rua Morro Agudo, 500 | F53: (17) 522-7130 | G53: Só 7 dígitos após o DDD — número incompleto | Q53: =IF(L53="","",IF(L53<=Preço!$C$7,Preço!$B$7,IF(L53<=Preço!$C$8,Preço!$B$8,IF(L53<=Preço!$C$9,Preço!$B$9,Preço!$B$10)))) | R53: =IF(L53="","",Preço!$D$7+MAX(0,MIN(L53,Preço!$C$8)-Preço!$C$7)*Preço!$D$8+MAX(0,MIN(L53,Preço!$C$9)-Preço!$C$8)*Preço!$D$9+MAX(0,L53-Preço!$C$9)*Preço!$D$10)
B54: 48 | C54: Condomínio Edifício Parque Residencial Estoril | D54: Vila Amendola | E54: Rua Treze de Maio, 1900 | F54: (17) 9102-7899 | G54: Celular sem o 9 — provavelmente falta um dígito | Q54: =IF(L54="","",IF(L54<=Preço!$C$7,Preço!$B$7,IF(L54<=Preço!$C$8,Preço!$B$8,IF(L54<=Preço!$C$9,Preço!$B$9,Preço!$B$10)))) | R54: =IF(L54="","",Preço!$D$7+MAX(0,MIN(L54,Preço!$C$8)-Preço!$C$7)*Preço!$D$8+MAX(0,MIN(L54,Preço!$C$9)-Preço!$C$8)*Preço!$D$9+MAX(0,L54-Preço!$C$9)*Preço!$D$10)
... B57: 51 | C57: Condomínio Edifício Manaus | D57:  | E57: Rua Manaus, 425 | F57: (17) 3522-4223 | G57: Telefone repetido em: Condomínio Edifício Amazonas | Q57: =IF(L57="","",IF(L57<=Preço!$C$7,Preço!$B$7,IF(L57<=Preço!$C$8,Preço!$B$8,IF(L57<=Preço!$C$9,Preço!$B$9,Preço!$B$10)))) | R57: =IF(L57="","",Preço!$D$7+MAX(0,MIN(L57,Preço!$C$8)-Preço!$C$7)*Preço!$D$8+MAX(0,MIN(L57,Preço!$C$9)-Preço!$C$8)*Preço!$D$9+MAX(0,L57-Preço!$C$9)*Preço!$D$10)
B58: 52 | C58: Condomínio Edifício Arquiteto Roberto Yazigi | D58: Centro | E58: Rua 13 de Maio, 337 | F58: sem telefone | Q58: =IF(L58="","",IF(L58<=Preço!$C$7,Preço!$B$7,IF(L58<=Preço!$C$8,Preço!$B$8,IF(L58<=Preço!$C$9,Preço!$B$9,Preço!$B$10)))) | R58: =IF(L58="","",Preço!$D$7+MAX(0,MIN(L58,Preço!$C$8)-Preço!$C$7)*Preço!$D$8+MAX(0,MIN(L58,Preço!$C$9)-Preço!$C$8)*Preço!$D$9+MAX(0,L58-Preço!$C$9)*Preço!$D$10)
B59: 53 | C59: Condomínio Edifício Caioba | D59: Centro | E59: Rua Ceará, 712 | F59: sem telefone | Q59: =IF(L59="","",IF(L59<=Preço!$C$7,Preço!$B$7,IF(L59<=Preço!$C$8,Preço!$B$8,IF(L59<=Preço!$C$9,Preço!$B$9,Preço!$B$10)))) | R59: =IF(L59="","",Preço!$D$7+MAX(0,MIN(L59,Preço!$C$8)-Preço!$C$7)*Preço!$D$8+MAX(0,MIN(L59,Preço!$C$9)-Preço!$C$8)*Preço!$D$9+MAX(0,L59-Preço!$C$9)*Preço!$D$10)
B60: 54 | C60: Condomínio Edifício Comendador Elias Wady | D60: Centro | E60: Rua Pernambuco, 267 | F60: sem telefone | Q60: =IF(L60="","",IF(L60<=Preço!$C$7,Preço!$B$7,IF(L60<=Preço!$C$8,Preço!$B$8,IF(L60<=Preço!$C$9,Preço!$B$9,Preço!$B$10)))) | R60: =IF(L60="","",Preço!$D$7+MAX(0,MIN(L60,Preço!$C$8)-Preço!$C$7)*Preço!$D$8+MAX(0,MIN(L60,Preço!$C$9)-Preço!$C$8)*Preço!$D$9+MAX(0,L60-Preço!$C$9)*Preço!$D$10)
B61: 55 | C61: Condomínio Edifício Estrela Maia | D61: Centro | E61: Rua Amazonas, 1577 | F61: sem telefone | Q61: =IF(L61="","",IF(L61<=Preço!$C$7,Preço!$B$7,IF(L61<=Preço!$C$8,Preço!$B$8,IF(L61<=Preço!$C$9,Preço!$B$9,Preço!$B$10)))) | R61: =IF(L61="","",Preço!$D$7+MAX(0,MIN(L61,Preço!$C$8)-Preço!$C$7)*Preço!$D$8+MAX(0,MIN(L61,Preço!$C$9)-Preço!$C$8)*Preço!$D$9+MAX(0,L61-Preço!$C$9)*Preço!$D$10)
B62: 56 | C62: Condomínio Edifício Residencial Antônio Dispore | D62: Centro | E62: Rua Recife, 585 | F62: sem telefone | Q62: =IF(L62="","",IF(L62<=Preço!$C$7,Preço!$B$7,IF(L62<=Preço!$C$8,Preço!$B$8,IF(L62<=Preço!$C$9,Preço!$B$9,Preço!$B$10)))) | R62: =IF(L62="","",Preço!$D$7+MAX(0,MIN(L62,Preço!$C$8)-Preço!$C$7)*Preço!$D$8+MAX(0,MIN(L62,Preço!$C$9)-Preço!$C$8)*Preço!$D$9+MAX(0,L62-Preço!$C$9)*Preço!$D$10)
B63: 57 | C63: Condomínio Edifício Residencial Fabiano Ramos | D63: Centro | E63: Rua Maranhão, 1560 | F63: sem telefone | Q63: =IF(L63="","",IF(L63<=Preço!$C$7,Preço!$B$7,IF(L63<=Preço!$C$8,Preço!$B$8,IF(L63<=Preço!$C$9,Preço!$B$9,Preço!$B$10)))) | R63: =IF(L63="","",Preço!$D$7+MAX(0,MIN(L63,Preço!$C$8)-Preço!$C$7)*Preço!$D$8+MAX(0,MIN(L63,Preço!$C$9)-Preço!$C$8)*Preço!$D$9+MAX(0,L63-Preço!$C$9)*Preço!$D$10)
B64: 58 | C64: Condomínio Edifício Residencial Monte Carlo | D64: Centro | E64: Rua Alagoas, 654 | F64: sem telefone | Q64: =IF(L64="","",IF(L64<=Preço!$C$7,Preço!$B$7,IF(L64<=Preço!$C$8,Preço!$B$8,IF(L64<=Preço!$C$9,Preço!$B$9,Preço!$B$10)))) | R64: =IF(L64="","",Preço!$D$7+MAX(0,MIN(L64,Preço!$C$8)-Preço!$C$7)*Preço!$D$8+MAX(0,MIN(L64,Preço!$C$9)-Preço!$C$8)*Preço!$D$9+MAX(0,L64-Preço!$C$9)*Preço!$D$10)
B65: 59 | C65: Condomínio Edifício Residencial Octávio Anovazzi | D65: Centro | E65: Rua Bahia, 1044 | F65: sem telefone | Q65: =IF(L65="","",IF(L65<=Preço!$C$7,Preço!$B$7,IF(L65<=Preço!$C$8,Preço!$B$8,IF(L65<=Preço!$C$9,Preço!$B$9,Preço!$B$10)))) | R65: =IF(L65="","",Preço!$D$7+MAX(0,MIN(L65,Preço!$C$8)-Preço!$C$7)*Preço!$D$8+MAX(0,MIN(L65,Preço!$C$9)-Preço!$C$8)*Preço!$D$9+MAX(0,L65-Preço!$C$9)*Preço!$D$10)
B66: 60 | C66: Condomínio Edifício Residencial Serra Negra | D66: Centro | E66: Rua Maranhão, 742 | F66: sem telefone | Q66: =IF(L66="","",IF(L66<=Preço!$C$7,Preço!$B$7,IF(L66<=Preço!$C$8,Preço!$B$8,IF(L66<=Preço!$C$9,Preço!$B$9,Preço!$B$10)))) | R66: =IF(L66="","",Preço!$D$7+MAX(0,MIN(L66,Preço!$C$8)-Preço!$C$7)*Preço!$D$8+MAX(0,MIN(L66,Preço!$C$9)-Preço!$C$8)*Preço!$D$9+MAX(0,L66-Preço!$C$9)*Preço!$D$10)
...

Sheet Telefones a conferir
B2: 15 telefones com problema — confira antes de ligar
B3: Números incompletos, DDD errado ou repetidos em prédios diferentes. Ligar assim é perder tempo.
B6: # | C6: Condomínio | D6: Telefone como está na sua lista | E6: O que está errado | F6: Telefone correto (preencher)
B7: 1 | C7: Condomínio Edifício Gaivotas | D7: (17) 5227-130 | E7: Só 7 dígitos após o DDD — número incompleto
B8: 2 | C8: Edifício Engenheiro José Nelson Machado | D8: +55 11 4020-2208 | E8: DDD 11 — Catanduva é DDD 17
B9: 3 | C9: Condomínio Edifício Parque Residencial Estoril | D9: 1791027899 | E9: Celular sem o 9 — provavelmente falta um dígito
B10: 4 | C10: Condomínio Residencial San Paolo | D10: (17) 5236-100 | E10: Só 7 dígitos após o DDD — número incompleto
B11: 5 | C11: Condomínio Edifício Manaus | D11: (17) 3522-4223 | E11: Telefone repetido em: Condomínio Edifício Amazonas
B12: 6 | C12: Condomínio Residencial Bahia | D12: (17) 3045-3650 | E12: Telefone repetido em: Condomínio Edifício Bahia
B13: 7 | C13: Condomínio Edifício Bahia | D13: (17) 3045-3650 | E13: Telefone repetido em: Condomínio Residencial Bahia
B14: 8 | C14: Condomínio Edifício Residencial Antônio Alonso Garcia | D14: (17) 3521-7019 | E14: Telefone repetido em: Condomínio Edifício João Alonso Garcia
B15: 9 | C15: Condomínio Residencial Gabriela | D15: (17) 5235-719 | E15: Só 7 dígitos após o DDD — número incompleto
B16: 10 | C16: Condomínio Edifício Amazonas | D16: 55 (17) 3522-4223 | E16: Telefone repetido em: Condomínio Edifício Manaus
B17: 11 | C17: Edifício Residencial Alvorada | D17: 17 3522.1257 | E17: Telefone repetido em: Residencial Jardim Alvorada; Condomínio Residencial Flamboyant
B18: 12 | C18: Condomínio Residencial Paineiras | D18: (17) 9724-9546 | E18: Celular sem o 9 — provavelmente falta um dígito
... B21: 15 | C21: Condomínio Residencial Félix Sahão | D21: (18) 3622-3544 | E21: DDD 18 — Catanduva é DDD 17

Sheet Faltam na sua lista
B2: 26 condomínios que não estão no seu arquivo
B3: Apareceram no levantamento público e não constam na sua planilha. Falta só o telefone.
B6: # | C6: Condomínio | D6: Endereço | E6: Bairro | F6: Telefone (preencher) | G6: Observação
B7: 1 | C7: Residencial Casa de Atenas | D7: Rua Uruguaiana, 2221 | E7: Jardim Glória
B8: 2 | C8: Residencial Casa de Viena | D8: Rua Uruguaiana, 2157 | E8: Jardim Glória
B9: 3 | C9: Condomínio Edifício do Café | D9: Praça da República, 6 | E9: Centro
B10: 4 | C10: Parque Casa Pienza | D10: Rua Doutor Cervantes Angulo, 295 | E10: Parque Joaquim Lopes | G10: É seu cliente (Casa Pienza) — só não estava no arquivo
B11: 5 | C11: Condomínio Residencial Varandas do Bosque | D11: Rua Campinas, 148 | E11: Jardim do Bosque
B12: 6 | C12: Condomínio Edifício Residencial Acapulco | D12: Rua Bahia, 521 | E12: Centro
B13: 7 | C13: Condomínio Edifício Comercial Minas Center | D13: Rua 21 de Abril, 466 | E13: Centro | G13: Comercial — mesmo assim tem síndico, portaria e encomenda
B14: 8 | C14: Condomínio Edifício Residencial San Remo | D14: Rua Ângelo Ceneviva, 137 | E14: San Remo
B15: 9 | C15: Condomínio Parque Casa de Leon | D15: Rua Uruguaiana, 1931 | E15: Parque Glória
B16: 10 | C16: Residencial Parque Casa de Cervantes | D16: Av. Manoel Francisco de Abreu, 272 | E16: Jardim Monte Carlo
B17: 11 | C17: Condomínio Edifício Catanduva Center Comercial | D17: Rua Treze de Maio, 271 | E17: Centro | G17: Comercial — mesmo assim tem síndico, portaria e encomenda
B18: 12 | C18: Parque Casa Bilbao | D18: Rua Colômbia, S/N | E18: Vila Juca Pedro
B19: 13 | C19: Condomínio Residencial Vitória Régia | D19: Rua Bahia, 235 | E19: Centro
B20: 14 | C20: Condomínio Edifício Drogasil-Catanduva | D20: Rua Brasil, 648 | E20: Centro | G20: Comercial — mesmo assim tem síndico, portaria e encomenda
B21: 15 | C21: Parque Casa de Málaga | D21: Rua Virgílio Mastrocola, 770 | E21: Vila Motta
B22: 16 | C22: Condomínio Edifício Professor Raul do Prado Vianna | D22: Rua Ceará, 527 | E22: Centro
B23: 17 | C23: Condomínio Residencial Antônio Simieli | D23: Rua Minas Gerais, 180 | E23: Centro
B24: 18 | C24: Condomínio Residencial Mirante da Bela Vista | D24: Rua Mogi Guaçu, 604 | E24: Jardim Santa Helena
B25: 19 | C25: Parque Casa Nova | D25: Rua Martinho Canozo, 250 | E25: Parque Joaquim Lopes
B26: 20 | C26: Condomínio Edifício Catanduva Shopping Center e Hotel | D26: Praça Monsenhor Albino, 114 | E26: Centro | G26: Comercial — mesmo assim tem síndico, portaria e encomenda
B27: 21 | C27: Conjunto Esportivo João Crippa | D27: Rua Colina, 65 | E27: Loteamento Cerradinho | G27: Comercial — mesmo assim tem síndico, portaria e encomenda
B28: 22 | C28: Condomínio Edifício Prefeito Duarte Nogueira II | D28: Rua Piracicaba, 1000 | E28: Santo Antônio | G28: Prédio vizinho ao seu cliente Duarte Nogueira I
B29: 23 | C29: Parque Casa Pueblo | D29: Av. Dona Engrácia A. Romão, 771 | E29: Vila Dona Engrácia
B30: 24 | C30: Condomínio Sunset Student House | D30: Rodovia Alfredo Jorge, 25 | E30: Jardim Oriental | G30: Moradia estudantil — verificar se é condomínio edilício
B31: 25 | C31: Vista Impper (em obras) | D31: Av. Eng. José Nelson Machado, 1659 | E31: Jardim Soto | G31: Em obras · 160 unidades e 20 pavimentos · síndico ainda em formação
B32: 26 | C32: Condomínio Residencial Idalina C. Kaiser

Sheet Já são seus clientes
B2: 11 condomínios do seu arquivo já são clientes da Prestare
B3: Não entre na fila de ligação como prospect — a conversa com eles é outra (migração para o app).
B6: # | C6: Condomínio no seu arquivo | D6: Bairro | E6: Telefone | F6: Unidades (sua carteira)
B7: 1 | C7: Condomínio Edifício Residencial Rio Negro | D7: Centro | E7: (17) 3524-3108 | F7: 24
B8: 2 | C8: Condomínio Solar dos Ipês | D8: Vila Rodrigues | E8: (17) 3522-7130 | F8: 64
B9: 3 | C9: Condomínio Edifício Residencial Porto Seguro | D9: Parque Iracema | F9: 12
B10: 4 | C10: Condomínio Edifício Grão Pará | D10: Centro | E10: (17) 3521-1330 | F10: 20
B11: 5 | C11: Condomínio Edifício Residencial Santos Dumont | D11: Jardim Amêndola | E11: (17) 3522-5687 | F11: 20
B12: 6 | C12: Edifício Residencial Santorini | D12: Jardim Vertoni | E12: (17) 3523-9019 | F12: 16
B13: 7 | C13: Residencial Santa Josefa | D13: Vila Juca Pedro | E13: (17) 3521-3776 | F13: 15
B14: 8 | C14: Condomínio Edifício Veredas do Sol | D14: Centro | E14: (17) 3524-2110 | F14: 22
B15: 9 | C15: Condomínio Edifício Prefeito Duarte Nogueira I | D15: Vila Maria Jorge | E15: (17) 3523-2891 | F15: 160
B16: 10 | C16: Residencial Jardim Alvorada | D16: Jardim do Lago | E16: (17) 3522-1257 | F16: 120
B17: 11 | C17: Edifício Residencial Moreschi | D17: Residencial Moreschi | F17: 24

Sheet Script da ligação
B2: O que falar quando o porteiro atender
B3: A ligação tem um objetivo só: o contato do síndico.
B5: ABERTURA
B6: "Boa tarde! Aqui é o Vinicius, da Prestare Gestão, administradora de condomínios aqui de Catanduva. Tudo bem? Preciso de uma informação rápida — você consegue me ajudar?"
B8: Porteiro atende bem quando você trata ele como pessoa e não como obstáculo. Não peça para "falar com o responsável": peça ajuda.
B11: AS TRÊS PERGUNTAS — nesta ordem
B12: 1. "Quantos apartamentos tem o prédio?" — comece por esta. É inofensiva, ele responde de cabeça, e é o dado que define o preço da sua proposta.
B14: 2. "Vocês usam algum aplicativo pra registrar visitante e encomenda, ou é no caderno mesmo?" — a resposta diz se você tem concorrente e já revela a dor. Se ele disser "é no caderno", anote a frase: ela vira o argumento da sua reunião com o síndico.
B16: 3. "Quem é o síndico hoje? Você tem o contato dele?" — só pergunte depois das duas primeiras. Perguntar isso de cara soa como venda e o porteiro fecha.
B19: SE ELE NÃO QUISER PASSAR O CONTATO
B20: "Sem problema, entendo. Você pode pedir pra ele me chamar no WhatsApp? Anota aí: Vinicius, da Prestare. É sobre um aplicativo que a gente lançou pra portaria e pro morador." Deixe o SEU número — funciona quase tão bem quanto pegar o dele.
B23: O QUE ANOTAR NA HORA
... B34: 20 ligações por dia, 4 dias = os 70 prédios da lista em uma semana. Com 30% de retorno, são cerca de 20 contatos de síndico — pipeline suficiente para encher a festa de lançamento.

Sheet Preço
B2: Tabela de preço por zonas
B3: Edite só o amarelo. Alimenta o cálculo da lista de ligação.
B6: Faixa | C6: Limite superior | D6: Valor | E6: Unidades
B7: Compacto | C7: 30 | D7: 298 | E7: Até 30 unidades
B8: Padrão | C8: 60 | D8: 9.9 | E8: Da 31ª à 60ª
B9: Plus | C9: 120 | D9: 8.9 | E9: Da 61ª à 120ª
B10: Corporativo | C10: — | D10: 11.9 | E10: Acima da 120ª
B12: Taxa de implantação (única) | D12: 490
